<?xml version="1.0"?>

<link name="lidar_link">
  <inertial>
    <origin xyz="0 0 0" rpy="0 0 0"/>
    <mass value="0.125"/>
    <inertia ixx="0.001" ixy="0" ixz="0" iyy="0.001" iyz="0" izz="0.001" />
  </inertial>

  <collision>
    <origin xyz="0 0 0" rpy="0 0 0"/>
    <geometry>
      <cylinder radius="0.035" length="0.055"/>
    </geometry>
  </collision>

  <visual>
    <origin xyz="0 0 0" rpy="0 0 0"/>
    <geometry>
      <cylinder radius="0.035" length="0.055"/>
    </geometry>
  </visual>
</link>

<joint name="lidar_joint" type="fixed">
  <parent link="base_link"/>
  <child link="lidar_link"/>
  <origin xyz="0 0 0.1418" rpy="0 0 0"/>
</joint>

<robot name="cstar_bot" xmlns:xacro="https://ros.org/wiki/xacro">

<!-- Define robot constants -->
<xacro:property name="base_radius" value="0.2412365"/>
<xacro:property name="base_height" value="0.2286"/>
<xacro:property name="wheel_radius" value="0.03176"/>
<xacro:property name="wheel_width" value="0.0254"/>
<xacro:property name="wheel_ygap" value="-0.0635"/>
<xacro:property name="wheel_zoff" value="0.0254"/>
<xacro:property name="wheel_xoff" value="0.0"/>
<xacro:property name="front_caster_xoff" value="0.1905"/>
<xacro:property name="front_caster_yoff" value="0.0"/>
<xacro:property name="back_caster_xoff" value="-0.1905"/>
<xacro:property name="back_caster_yoff" value="0.0"/>
<xacro:property name="laser_radius" value="0.035"/>
<xacro:property name="laser_height" value="0.055"/>

<!-- Inertial properties -->
<xacro:macro name="cylinder_inertia" params="m r h">
    <inertial>
      <origin xyz="0 0 0" rpy="${pi/2} 0 0" />
      <mass value="${m}"/>
      <inertia ixx="${(m/12) * (3*r*r + h*h)}" ixy = "0" ixz = "0" iyy="${(m/12) * (3*r*r + h*h)}" iyz = "0" izz="${(m/2) * (r*r)}"/>
    </inertial>
  </xacro:macro>

  <xacro:macro name="sphere_inertia" params="m r">
    <inertial>
      <mass value="${m}"/>
      <inertia ixx="${(2/5) * m * (r*r)}" ixy="0.0" ixz="0.0" iyy="${(2/5) * m * (r*r)}" iyz="0.0" izz="${(2/5) * m * (r*r)}"/>
    </inertial>
</xacro:macro>

<!-- Robot Base -->
<link name="base_link">
    <visual>
      <geometry>
        <cylinder radius="${base_radius}" length="${base_height}"/>
      </geometry>
      <material name="Cyan">
        <color rgba="0 1.0 1.0 1.0"/>
      </material>
    </visual>
</link>

<link name="base_link_dummy">
    <collision>
      <geometry>
        <cylinder radius="${base_radius}" length="${base_height}"/>
      </geometry>
    </collision>
    
    <xacro:cylinder_inertia m="0.5" r="${base_radius}" h="${base_height}"/>
</link>

<joint name="dummy_joint" type="fixed">
    <parent link="base_link"/>
    <child link="base_link_dummy"/>
</joint>

<!-- Robot Footprint -->
<link name="base_footprint"/>

<joint name="base_joint" type="fixed">
    <parent link="base_link"/>
    <child link="base_footprint"/>
    <origin xyz="0.0 0.0 ${-(wheel_zoff + base_height/2 + wheel_radius)}" rpy="0 0 0"/>
</joint>

<!-- Wheels -->
<xacro:macro name="wheel" params="prefix x_reflect y_reflect">
  <link name="${prefix}_link">
      <visual>
        <origin xyz="0 0 0" rpy="${pi/2} 0 0"/>
        <geometry>
          <cylinder radius="${wheel_radius}" length="${wheel_width}"/>
        </geometry>
        <material name="Gray">
          <color rgba="0.5 0.5 0.5 1.0"/>
        </material>
      </visual>

      <collision>
        <origin xyz="0 0 0" rpy="${pi/2} 0 0"/>
        <geometry>
          <cylinder radius="${wheel_radius}" length="${wheel_width}"/>
        </geometry>
      </collision>

      <xacro:cylinder_inertia m="0.5" r="${wheel_radius}" h="${wheel_width}"/>
  </link>

  <joint name="${prefix}_joint" type="continuous">
      <parent link="base_link"/>
      <child link="${prefix}_link"/>
      <origin xyz="${x_reflect * wheel_xoff} ${y_reflect * (base_radius + wheel_ygap)} ${-(wheel_zoff + base_height/2)}" rpy="0 0 0"/>
      <axis xyz="0 1 0"/>
  </joint>
</xacro:macro>

<xacro:wheel prefix="drivewhl_l" x_reflect="-1" y_reflect="1"/>
<xacro:wheel prefix="drivewhl_r" x_reflect="-1" y_reflect="-1"/>
  
<!-- Front Caster Wheel -->
<link name="front_caster">
    <visual>
      <geometry>
        <sphere radius="${wheel_radius}"/>
      </geometry>
      <material name="Cyan">
        <color rgba="0 1.0 1.0 1.0"/>
      </material>
    </visual>

    <collision>
      <geometry>
        <sphere radius="${wheel_radius}"/>
      </geometry>
    </collision>

    <xacro:sphere_inertia m="0.5" r="${wheel_radius}"/>
</link>

<joint name="front_caster_joint" type="fixed">
    <parent link="base_link"/>
    <child link="front_caster"/>
    <origin xyz="${front_caster_xoff} ${front_caster_yoff} ${-(wheel_zoff + base_height/2)}" rpy="0 0 0"/>
</joint>

<!-- Back Caster Wheel -->
<link name="back_caster">
    <visual>
      <geometry>
        <sphere radius="${wheel_radius}"/>
      </geometry>
      <material name="Cyan">
        <color rgba="0 1.0 1.0 1.0"/>
      </material>
    </visual>

    <collision>
      <geometry>
        <sphere radius="${wheel_radius}"/>
      </geometry>
    </collision>

    <xacro:sphere_inertia m="0.5" r="${wheel_radius}"/>
</link>

<joint name="back_caster_joint" type="fixed">
    <parent link="base_link"/>
    <child link="back_caster"/>
    <origin xyz="${back_caster_xoff} ${back_caster_yoff} ${-(wheel_zoff + base_height/2)}" rpy="0 0 0"/>
</joint>

<!-- LiDAR sensor
<link name="base_laser">
    <visual>
      <geometry>
        <cylinder radius="${laser_radius}" length="${laser_height}"/>
      </geometry>
      <material name="Black">
        <color rgba="0 0 0 1.0"/>
      </material>
    </visual>

    <collision>
      <geometry>
        <cylinder radius="${laser_radius}" length="${laser_height}"/>
      </geometry>
    </collision>

    <xacro:cylinder_inertia m="0.5" r="${laser_radius}" h="${laser_height}"/>
</link>

<joint name="laser_joint" type="continuous">
    <parent link="base_link"/>
    <child link="base_laser"/>
    <origin xyz="0 0 ${base_height/2 + laser_height/2}" rpy="0 0 0"/>
    <axis xyz="0 0 1"/>
</joint> -->

</robot>